Workbook
Name IncomeCategories: 'Categories'!$A$3:$A$6
Name MainCategories: 'Categories'!$F$3:$F$12
Name Cat_Land_Legal: 'Categories'!$H$3:$H$9
Name Cat_Site_Development: 'Categories'!$I$3:$I$11
Name Cat_Utilities: 'Categories'!$J$3:$J$9
Name Cat_Landscaping: 'Categories'!$K$3:$K$7
Name Cat_Buildings_Amenities: 'Categories'!$L$3:$L$10
Name Cat_Labour_Contractors: 'Categories'!$M$3:$M$7
Name Cat_Materials: 'Categories'!$N$3:$N$11
Name Cat_Operations: 'Categories'!$O$3:$O$9
Name Cat_Marketing_Sales: 'Categories'!$P$3:$P$8
Name Cat_Miscellaneous: 'Categories'!$Q$3:$Q$7

Sheet Dashboard
A1: Site Expense Dashboard
A3: Current Cash Balance | C3: YTD Total Receipts | E3: YTD Total Payments | G3: Net Position (YTD)
A4: ='Dec2026'!B106 | C4: =SUM(B45:B56) | E4: =SUM(C45:C56) | G4: =C4-E4
A44: Month | B44: Receipts | C44: Payments | D44: Closing Balance | F44: Main Category | G44: Amount | I44: Income Category | J44: Amount | L44: Payment Mode | M44: Amount
A45: Jan2026 | B45: ='Jan2026'!B104 | C45: ='Jan2026'!B105 | D45: ='Jan2026'!B106 | F45: Land & Legal | G45: =SUMIFS(Jan2026!K3:K100,Jan2026!L3:L100,$F45)+SUMIFS(Feb2026!K3:K100,Feb2026!L3:L100,$F45)+SUMIFS(Mar2026!K3:K100,Mar2026!L3:L100,$F45)+SUMIFS(Apr2026!K3:K100,Apr2026!L3:L100,$F45)+SUMIFS(May2026!K3:K100,May2026!L3:L100,$F45)+SUMIFS(Jun2026!K3:K100,Jun2026!L3:L100,$F45)+SUMIFS(Jul2026!K3:K100,Jul2026!L3:L100,$F45)+SUMIFS(Aug2026!K3:K100,Aug2026!L3:L100,$F45)+SUMIFS(Sep2026!K3:K100,Sep2026!L3:L100,$F45)+SUMIFS(Oct2026!K3:K100,Oct2026!L3:L100,$F45)+SUMIFS(Nov2026!K3:K100,Nov2026!L3:L100,$F45)+SUMIFS(Dec2026!K3:K100,Dec2026!L3:L100,$F45) | I45: Investor Capital | J45: =SUMIFS(Jan2026!D3:D100,Jan2026!E3:E100,$I45)+SUMIFS(Feb2026!D3:D100,Feb2026!E3:E100,$I45)+SUMIFS(Mar2026!D3:D100,Mar2026!E3:E100,$I45)+SUMIFS(Apr2026!D3:D100,Apr2026!E3:E100,$I45)+SUMIFS(May2026!D3:D100,May2026!E3:E100,$I45)+SUMIFS(Jun2026!D3:D100,Jun2026!E3:E100,$I45)+SUMIFS(Jul2026!D3:D100,Jul2026!E3:E100,$I45)+SUMIFS(Aug2026!D3:D100,Aug2026!E3:E100,$I45)+SUMIFS(Sep2026!D3:D100,Sep2026!E3:E100,$I45)+SUMIFS(Oct2026!D3:D100,Oct2026!E3:E100,$I45)+SUMIFS(Nov2026!D3:D100,Nov2026!E3:E100,$I45)+SUMIFS(Dec2026!D3:D100,Dec2026!E3:E100,$I45) | L45: Bank | M45: =SUMIFS(Jan2026!D3:D100,Jan2026!F3:F100,$L45)+SUMIFS(Jan2026!K3:K100,Jan2026!N3:N100,$L45)+SUMIFS(Feb2026!D3:D100,Feb2026!F3:F100,$L45)+SUMIFS(Feb2026!K3:K100,Feb2026!N3:N100,$L45)+SUMIFS(Mar2026!D3:D100,Mar2026!F3:F100,$L45)+SUMIFS(Mar2026!K3:K100,Mar2026!N3:N100,$L45)+SUMIFS(Apr2026!D3:D100,Apr2026!F3:F100,$L45)+SUMIFS(Apr2026!K3:K100,Apr2026!N3:N100,$L45)+SUMIFS(May2026!D3:D100,May2026!F3:F100,$L45)+SUMIFS(May2026!K3:K100,May2026!N3:N100,$L45)+SUMIFS(Jun2026!D3:D100,Jun2026!F3:F100,$L45)+SUMIFS(Jun2026!K3:K100,Jun2026!N3:N100,$L45)+SUMIFS(Jul2026!D3:D100,Jul2026!F3:F100,$L45)+SUMIFS(Jul2026!K3:K100,Jul2026!N3:N100,$L45)+SUMIFS(Aug2026!D3:D100,Aug2026!F3:F100,$L45)+SUMIFS(Aug2026!K3:K100,Aug2026!N3:N100,$L45)+SUMIFS(Sep2026!D3:D100,Sep2026!F3:F100,$L45)+SUMIFS(Sep2026!K3:K100,Sep2026!N3:N100,$L45)+SUMIFS(Oct2026!D3:D100,Oct2026!F3:F100,$L45)+SUMIFS(Oct2026!K3:K100,Oct2026!N3:N100,$L45)+SUMIFS(Nov2026!D3:D100,Nov2026!F3:F100,$L45)+SUMIFS(Nov2026!K3:K100,Nov2026!N3:N100,$L45)+SUMIFS(Dec2026!D3:D100,Dec2026!F3:F100,$L45)+SUMIFS(Dec2026!K3:K100,Dec2026!N3:N100,$L45)
A46: Feb2026 | B46: ='Feb2026'!B104 | C46: ='Feb2026'!B105 | D46: ='Feb2026'!B106 | F46: Site Development | G46: =SUMIFS(Jan2026!K3:K100,Jan2026!L3:L100,$F46)+SUMIFS(Feb2026!K3:K100,Feb2026!L3:L100,$F46)+SUMIFS(Mar2026!K3:K100,Mar2026!L3:L100,$F46)+SUMIFS(Apr2026!K3:K100,Apr2026!L3:L100,$F46)+SUMIFS(May2026!K3:K100,May2026!L3:L100,$F46)+SUMIFS(Jun2026!K3:K100,Jun2026!L3:L100,$F46)+SUMIFS(Jul2026!K3:K100,Jul2026!L3:L100,$F46)+SUMIFS(Aug2026!K3:K100,Aug2026!L3:L100,$F46)+SUMIFS(Sep2026!K3:K100,Sep2026!L3:L100,$F46)+SUMIFS(Oct2026!K3:K100,Oct2026!L3:L100,$F46)+SUMIFS(Nov2026!K3:K100,Nov2026!L3:L100,$F46)+SUMIFS(Dec2026!K3:K100,Dec2026!L3:L100,$F46) | I46: Partner Contribution | J46: =SUMIFS(Jan2026!D3:D100,Jan2026!E3:E100,$I46)+SUMIFS(Feb2026!D3:D100,Feb2026!E3:E100,$I46)+SUMIFS(Mar2026!D3:D100,Mar2026!E3:E100,$I46)+SUMIFS(Apr2026!D3:D100,Apr2026!E3:E100,$I46)+SUMIFS(May2026!D3:D100,May2026!E3:E100,$I46)+SUMIFS(Jun2026!D3:D100,Jun2026!E3:E100,$I46)+SUMIFS(Jul2026!D3:D100,Jul2026!E3:E100,$I46)+SUMIFS(Aug2026!D3:D100,Aug2026!E3:E100,$I46)+SUMIFS(Sep2026!D3:D100,Sep2026!E3:E100,$I46)+SUMIFS(Oct2026!D3:D100,Oct2026!E3:E100,$I46)+SUMIFS(Nov2026!D3:D100,Nov2026!E3:E100,$I46)+SUMIFS(Dec2026!D3:D100,Dec2026!E3:E100,$I46) | L46: Cash | M46: =SUMIFS(Jan2026!D3:D100,Jan2026!F3:F100,$L46)+SUMIFS(Jan2026!K3:K100,Jan2026!N3:N100,$L46)+SUMIFS(Feb2026!D3:D100,Feb2026!F3:F100,$L46)+SUMIFS(Feb2026!K3:K100,Feb2026!N3:N100,$L46)+SUMIFS(Mar2026!D3:D100,Mar2026!F3:F100,$L46)+SUMIFS(Mar2026!K3:K100,Mar2026!N3:N100,$L46)+SUMIFS(Apr2026!D3:D100,Apr2026!F3:F100,$L46)+SUMIFS(Apr2026!K3:K100,Apr2026!N3:N100,$L46)+SUMIFS(May2026!D3:D100,May2026!F3:F100,$L46)+SUMIFS(May2026!K3:K100,May2026!N3:N100,$L46)+SUMIFS(Jun2026!D3:D100,Jun2026!F3:F100,$L46)+SUMIFS(Jun2026!K3:K100,Jun2026!N3:N100,$L46)+SUMIFS(Jul2026!D3:D100,Jul2026!F3:F100,$L46)+SUMIFS(Jul2026!K3:K100,Jul2026!N3:N100,$L46)+SUMIFS(Aug2026!D3:D100,Aug2026!F3:F100,$L46)+SUMIFS(Aug2026!K3:K100,Aug2026!N3:N100,$L46)+SUMIFS(Sep2026!D3:D100,Sep2026!F3:F100,$L46)+SUMIFS(Sep2026!K3:K100,Sep2026!N3:N100,$L46)+SUMIFS(Oct2026!D3:D100,Oct2026!F3:F100,$L46)+SUMIFS(Oct2026!K3:K100,Oct2026!N3:N100,$L46)+SUMIFS(Nov2026!D3:D100,Nov2026!F3:F100,$L46)+SUMIFS(Nov2026!K3:K100,Nov2026!N3:N100,$L46)+SUMIFS(Dec2026!D3:D100,Dec2026!F3:F100,$L46)+SUMIFS(Dec2026!K3:K100,Dec2026!N3:N100,$L46)
A47: Mar2026 | B47: ='Mar2026'!B104 | C47: ='Mar2026'!B105 | D47: ='Mar2026'!B106 | F47: Utilities | G47: =SUMIFS(Jan2026!K3:K100,Jan2026!L3:L100,$F47)+SUMIFS(Feb2026!K3:K100,Feb2026!L3:L100,$F47)+SUMIFS(Mar2026!K3:K100,Mar2026!L3:L100,$F47)+SUMIFS(Apr2026!K3:K100,Apr2026!L3:L100,$F47)+SUMIFS(May2026!K3:K100,May2026!L3:L100,$F47)+SUMIFS(Jun2026!K3:K100,Jun2026!L3:L100,$F47)+SUMIFS(Jul2026!K3:K100,Jul2026!L3:L100,$F47)+SUMIFS(Aug2026!K3:K100,Aug2026!L3:L100,$F47)+SUMIFS(Sep2026!K3:K100,Sep2026!L3:L100,$F47)+SUMIFS(Oct2026!K3:K100,Oct2026!L3:L100,$F47)+SUMIFS(Nov2026!K3:K100,Nov2026!L3:L100,$F47)+SUMIFS(Dec2026!K3:K100,Dec2026!L3:L100,$F47) | I47: Loan Received | J47: =SUMIFS(Jan2026!D3:D100,Jan2026!E3:E100,$I47)+SUMIFS(Feb2026!D3:D100,Feb2026!E3:E100,$I47)+SUMIFS(Mar2026!D3:D100,Mar2026!E3:E100,$I47)+SUMIFS(Apr2026!D3:D100,Apr2026!E3:E100,$I47)+SUMIFS(May2026!D3:D100,May2026!E3:E100,$I47)+SUMIFS(Jun2026!D3:D100,Jun2026!E3:E100,$I47)+SUMIFS(Jul2026!D3:D100,Jul2026!E3:E100,$I47)+SUMIFS(Aug2026!D3:D100,Aug2026!E3:E100,$I47)+SUMIFS(Sep2026!D3:D100,Sep2026!E3:E100,$I47)+SUMIFS(Oct2026!D3:D100,Oct2026!E3:E100,$I47)+SUMIFS(Nov2026!D3:D100,Nov2026!E3:E100,$I47)+SUMIFS(Dec2026!D3:D100,Dec2026!E3:E100,$I47)
A48: Apr2026 | B48: ='Apr2026'!B104 | C48: ='Apr2026'!B105 | D48: ='Apr2026'!B106 | F48: Landscaping | G48: =SUMIFS(Jan2026!K3:K100,Jan2026!L3:L100,$F48)+SUMIFS(Feb2026!K3:K100,Feb2026!L3:L100,$F48)+SUMIFS(Mar2026!K3:K100,Mar2026!L3:L100,$F48)+SUMIFS(Apr2026!K3:K100,Apr2026!L3:L100,$F48)+SUMIFS(May2026!K3:K100,May2026!L3:L100,$F48)+SUMIFS(Jun2026!K3:K100,Jun2026!L3:L100,$F48)+SUMIFS(Jul2026!K3:K100,Jul2026!L3:L100,$F48)+SUMIFS(Aug2026!K3:K100,Aug2026!L3:L100,$F48)+SUMIFS(Sep2026!K3:K100,Sep2026!L3:L100,$F48)+SUMIFS(Oct2026!K3:K100,Oct2026!L3:L100,$F48)+SUMIFS(Nov2026!K3:K100,Nov2026!L3:L100,$F48)+SUMIFS(Dec2026!K3:K100,Dec2026!L3:L100,$F48) | I48: Sales | J48: =SUMIFS(Jan2026!D3:D100,Jan2026!E3:E100,$I48)+SUMIFS(Feb2026!D3:D100,Feb2026!E3:E100,$I48)+SUMIFS(Mar2026!D3:D100,Mar2026!E3:E100,$I48)+SUMIFS(Apr2026!D3:D100,Apr2026!E3:E100,$I48)+SUMIFS(May2026!D3:D100,May2026!E3:E100,$I48)+SUMIFS(Jun2026!D3:D100,Jun2026!E3:E100,$I48)+SUMIFS(Jul2026!D3:D100,Jul2026!E3:E100,$I48)+SUMIFS(Aug2026!D3:D100,Aug2026!E3:E100,$I48)+SUMIFS(Sep2026!D3:D100,Sep2026!E3:E100,$I48)+SUMIFS(Oct2026!D3:D100,Oct2026!E3:E100,$I48)+SUMIFS(Nov2026!D3:D100,Nov2026!E3:E100,$I48)+SUMIFS(Dec2026!D3:D100,Dec2026!E3:E100,$I48)
A49: May2026 | B49: ='May2026'!B104 | C49: ='May2026'!B105 | D49: ='May2026'!B106 | F49: Buildings & Amenities | G49: =SUMIFS(Jan2026!K3:K100,Jan2026!L3:L100,$F49)+SUMIFS(Feb2026!K3:K100,Feb2026!L3:L100,$F49)+SUMIFS(Mar2026!K3:K100,Mar2026!L3:L100,$F49)+SUMIFS(Apr2026!K3:K100,Apr2026!L3:L100,$F49)+SUMIFS(May2026!K3:K100,May2026!L3:L100,$F49)+SUMIFS(Jun2026!K3:K100,Jun2026!L3:L100,$F49)+SUMIFS(Jul2026!K3:K100,Jul2026!L3:L100,$F49)+SUMIFS(Aug2026!K3:K100,Aug2026!L3:L100,$F49)+SUMIFS(Sep2026!K3:K100,Sep2026!L3:L100,$F49)+SUMIFS(Oct2026!K3:K100,Oct2026!L3:L100,$F49)+SUMIFS(Nov2026!K3:K100,Nov2026!L3:L100,$F49)+SUMIFS(Dec2026!K3:K100,Dec2026!L3:L100,$F49)
A50: Jun2026 | B50: ='Jun2026'!B104 | C50: ='Jun2026'!B105 | D50: ='Jun2026'!B106 | F50: Labour & Contractors | G50: =SUMIFS(Jan2026!K3:K100,Jan2026!L3:L100,$F50)+SUMIFS(Feb2026!K3:K100,Feb2026!L3:L100,$F50)+SUMIFS(Mar2026!K3:K100,Mar2026!L3:L100,$F50)+SUMIFS(Apr2026!K3:K100,Apr2026!L3:L100,$F50)+SUMIFS(May2026!K3:K100,May2026!L3:L100,$F50)+SUMIFS(Jun2026!K3:K100,Jun2026!L3:L100,$F50)+SUMIFS(Jul2026!K3:K100,Jul2026!L3:L100,$F50)+SUMIFS(Aug2026!K3:K100,Aug2026!L3:L100,$F50)+SUMIFS(Sep2026!K3:K100,Sep2026!L3:L100,$F50)+SUMIFS(Oct2026!K3:K100,Oct2026!L3:L100,$F50)+SUMIFS(Nov2026!K3:K100,Nov2026!L3:L100,$F50)+SUMIFS(Dec2026!K3:K100,Dec2026!L3:L100,$F50)
A51: Jul2026 | B51: ='Jul2026'!B104 | C51: ='Jul2026'!B105 | D51: ='Jul2026'!B106 | F51: Materials | G51: =SUMIFS(Jan2026!K3:K100,Jan2026!L3:L100,$F51)+SUMIFS(Feb2026!K3:K100,Feb2026!L3:L100,$F51)+SUMIFS(Mar2026!K3:K100,Mar2026!L3:L100,$F51)+SUMIFS(Apr2026!K3:K100,Apr2026!L3:L100,$F51)+SUMIFS(May2026!K3:K100,May2026!L3:L100,$F51)+SUMIFS(Jun2026!K3:K100,Jun2026!L3:L100,$F51)+SUMIFS(Jul2026!K3:K100,Jul2026!L3:L100,$F51)+SUMIFS(Aug2026!K3:K100,Aug2026!L3:L100,$F51)+SUMIFS(Sep2026!K3:K100,Sep2026!L3:L100,$F51)+SUMIFS(Oct2026!K3:K100,Oct2026!L3:L100,$F51)+SUMIFS(Nov2026!K3:K100,Nov2026!L3:L100,$F51)+SUMIFS(Dec2026!K3:K100,Dec2026!L3:L100,$F51)
A52: Aug2026 | B52: ='Aug2026'!B104 | C52: ='Aug2026'!B105 | D52: ='Aug2026'!B106 | F52: Operations | G52: =SUMIFS(Jan2026!K3:K100,Jan2026!L3:L100,$F52)+SUMIFS(Feb2026!K3:K100,Feb2026!L3:L100,$F52)+SUMIFS(Mar2026!K3:K100,Mar2026!L3:L100,$F52)+SUMIFS(Apr2026!K3:K100,Apr2026!L3:L100,$F52)+SUMIFS(May2026!K3:K100,May2026!L3:L100,$F52)+SUMIFS(Jun2026!K3:K100,Jun2026!L3:L100,$F52)+SUMIFS(Jul2026!K3:K100,Jul2026!L3:L100,$F52)+SUMIFS(Aug2026!K3:K100,Aug2026!L3:L100,$F52)+SUMIFS(Sep2026!K3:K100,Sep2026!L3:L100,$F52)+SUMIFS(Oct2026!K3:K100,Oct2026!L3:L100,$F52)+SUMIFS(Nov2026!K3:K100,Nov2026!L3:L100,$F52)+SUMIFS(Dec2026!K3:K100,Dec2026!L3:L100,$F52)
A53: Sep2026 | B53: ='Sep2026'!B104 | C53: ='Sep2026'!B105 | D53: ='Sep2026'!B106 | F53: Marketing & Sales | G53: =SUMIFS(Jan2026!K3:K100,Jan2026!L3:L100,$F53)+SUMIFS(Feb2026!K3:K100,Feb2026!L3:L100,$F53)+SUMIFS(Mar2026!K3:K100,Mar2026!L3:L100,$F53)+SUMIFS(Apr2026!K3:K100,Apr2026!L3:L100,$F53)+SUMIFS(May2026!K3:K100,May2026!L3:L100,$F53)+SUMIFS(Jun2026!K3:K100,Jun2026!L3:L100,$F53)+SUMIFS(Jul2026!K3:K100,Jul2026!L3:L100,$F53)+SUMIFS(Aug2026!K3:K100,Aug2026!L3:L100,$F53)+SUMIFS(Sep2026!K3:K100,Sep2026!L3:L100,$F53)+SUMIFS(Oct2026!K3:K100,Oct2026!L3:L100,$F53)+SUMIFS(Nov2026!K3:K100,Nov2026!L3:L100,$F53)+SUMIFS(Dec2026!K3:K100,Dec2026!L3:L100,$F53)
A54: Oct2026 | B54: ='Oct2026'!B104 | C54: ='Oct2026'!B105 | D54: ='Oct2026'!B106 | F54: Miscellaneous | G54: =SUMIFS(Jan2026!K3:K100,Jan2026!L3:L100,$F54)+SUMIFS(Feb2026!K3:K100,Feb2026!L3:L100,$F54)+SUMIFS(Mar2026!K3:K100,Mar2026!L3:L100,$F54)+SUMIFS(Apr2026!K3:K100,Apr2026!L3:L100,$F54)+SUMIFS(May2026!K3:K100,May2026!L3:L100,$F54)+SUMIFS(Jun2026!K3:K100,Jun2026!L3:L100,$F54)+SUMIFS(Jul2026!K3:K100,Jul2026!L3:L100,$F54)+SUMIFS(Aug2026!K3:K100,Aug2026!L3:L100,$F54)+SUMIFS(Sep2026!K3:K100,Sep2026!L3:L100,$F54)+SUMIFS(Oct2026!K3:K100,Oct2026!L3:L100,$F54)+SUMIFS(Nov2026!K3:K100,Nov2026!L3:L100,$F54)+SUMIFS(Dec2026!K3:K100,Dec2026!L3:L100,$F54)
A55: Nov2026 | B55: ='Nov2026'!B104 | C55: ='Nov2026'!B105 | D55: ='Nov2026'!B106
A56: Dec2026 | B56: ='Dec2026'!B104 | C56: ='Dec2026'!B105 | D56: ='Dec2026'!B106
A60: Main Category | B60: Sub-Category | C60: Amount
A61: Land & Legal | B61: Land Purchase | C61: =SUMIFS(Jan2026!K3:K100,Jan2026!L3:L100,$A61,Jan2026!M3:M100,$B61)+SUMIFS(Feb2026!K3:K100,Feb2026!L3:L100,$A61,Feb2026!M3:M100,$B61)+SUMIFS(Mar2026!K3:K100,Mar2026!L3:L100,$A61,Mar2026!M3:M100,$B61)+SUMIFS(Apr2026!K3:K100,Apr2026!L3:L100,$A61,Apr2026!M3:M100,$B61)+SUMIFS(May2026!K3:K100,May2026!L3:L100,$A61,May2026!M3:M100,$B61)+SUMIFS(Jun2026!K3:K100,Jun2026!L3:L100,$A61,Jun2026!M3:M100,$B61)+SUMIFS(Jul2026!K3:K100,Jul2026!L3:L100,$A61,Jul2026!M3:M100,$B61)+SUMIFS(Aug2026!K3:K100,Aug2026!L3:L100,$A61,Aug2026!M3:M100,$B61)+SUMIFS(Sep2026!K3:K100,Sep2026!L3:L100,$A61,Sep2026!M3:M100,$B61)+SUMIFS(Oct2026!K3:K100,Oct2026!L3:L100,$A61,Oct2026!M3:M100,$B61)+SUMIFS(Nov2026!K3:K100,Nov2026!L3:L100,$A61,Nov2026!M3:M100,$B61)+SUMIFS(Dec2026!K3:K100,Dec2026!L3:L100,$A61,Dec2026!M3:M100,$B61)
A62: Land & Legal | B62: Advance Payments | C62: =SUMIFS(Jan2026!K3:K100,Jan2026!L3:L100,$A62,Jan2026!M3:M100,$B62)+SUMIFS(Feb2026!K3:K100,Feb2026!L3:L100,$A62,Feb2026!M3:M100,$B62)+SUMIFS(Mar2026!K3:K100,Mar2026!L3:L100,$A62,Mar2026!M3:M100,$B62)+SUMIFS(Apr2026!K3:K100,Apr2026!L3:L100,$A62,Apr2026!M3:M100,$B62)+SUMIFS(May2026!K3:K100,May2026!L3:L100,$A62,May2026!M3:M100,$B62)+SUMIFS(Jun2026!K3:K100,Jun2026!L3:L100,$A62,Jun2026!M3:M100,$B62)+SUMIFS(Jul2026!K3:K100,Jul2026!L3:L100,$A62,Jul2026!M3:M100,$B62)+SUMIFS(Aug2026!K3:K100,Aug2026!L3:L100,$A62,Aug2026!M3:M100,$B62)+SUMIFS(Sep2026!K3:K100,Sep2026!L3:L100,$A62,Sep2026!M3:M100,$B62)+SUMIFS(Oct2026!K3:K100,Oct2026!L3:L100,$A62,Oct2026!M3:M100,$B62)+SUMIFS(Nov2026!K3:K100,Nov2026!L3:L100,$A62,Nov2026!M3:M100,$B62)+SUMIFS(Dec2026!K3:K100,Dec2026!L3:L100,$A62,Dec2026!M3:M100,$B62)
A63: Land & Legal | B63: Registration Charges | C63: =SUMIFS(Jan2026!K3:K100,Jan2026!L3:L100,$A63,Jan2026!M3:M100,$B63)+SUMIFS(Feb2026!K3:K100,Feb2026!L3:L100,$A63,Feb2026!M3:M100,$B63)+SUMIFS(Mar2026!K3:K100,Mar2026!L3:L100,$A63,Mar2026!M3:M100,$B63)+SUMIFS(Apr2026!K3:K100,Apr2026!L3:L100,$A63,Apr2026!M3:M100,$B63)+SUMIFS(May2026!K3:K100,May2026!L3:L100,$A63,May2026!M3:M100,$B63)+SUMIFS(Jun2026!K3:K100,Jun2026!L3:L100,$A63,Jun2026!M3:M100,$B63)+SUMIFS(Jul2026!K3:K100,Jul2026!L3:L100,$A63,Jul2026!M3:M100,$B63)+SUMIFS(Aug2026!K3:K100,Aug2026!L3:L100,$A63,Aug2026!M3:M100,$B63)+SUMIFS(Sep2026!K3:K100,Sep2026!L3:L100,$A63,Sep2026!M3:M100,$B63)+SUMIFS(Oct2026!K3:K100,Oct2026!L3:L100,$A63,Oct2026!M3:M100,$B63)+SUMIFS(Nov2026!K3:K100,Nov2026!L3:L100,$A63,Nov2026!M3:M100,$B63)+SUMIFS(Dec2026!K3:K100,Dec2026!L3:L100,$A63,Dec2026!M3:M100,$B63)
A64: Land & Legal | B64: Stamp Duty | C64: =SUMIFS(Jan2026!K3:K100,Jan2026!L3:L100,$A64,Jan2026!M3:M100,$B64)+SUMIFS(Feb2026!K3:K100,Feb2026!L3:L100,$A64,Feb2026!M3:M100,$B64)+SUMIFS(Mar2026!K3:K100,Mar2026!L3:L100,$A64,Mar2026!M3:M100,$B64)+SUMIFS(Apr2026!K3:K100,Apr2026!L3:L100,$A64,Apr2026!M3:M100,$B64)+SUMIFS(May2026!K3:K100,May2026!L3:L100,$A64,May2026!M3:M100,$B64)+SUMIFS(Jun2026!K3:K100,Jun2026!L3:L100,$A64,Jun2026!M3:M100,$B64)+SUMIFS(Jul2026!K3:K100,Jul2026!L3:L100,$A64,Jul2026!M3:M100,$B64)+SUMIFS(Aug2026!K3:K100,Aug2026!L3:L100,$A64,Aug2026!M3:M100,$B64)+SUMIFS(Sep2026!K3:K100,Sep2026!L3:L100,$A64,Sep2026!M3:M100,$B64)+SUMIFS(Oct2026!K3:K100,Oct2026!L3:L100,$A64,Oct2026!M3:M100,$B64)+SUMIFS(Nov2026!K3:K100,Nov2026!L3:L100,$A64,Nov2026!M3:M100,$B64)+SUMIFS(Dec2026!K3:K100,Dec2026!L3:L100,$A64,Dec2026!M3:M100,$B64)
A65: Land & Legal | B65: Legal Fees | C65: =SUMIFS(Jan2026!K3:K100,Jan2026!L3:L100,$A65,Jan2026!M3:M100,$B65)+SUMIFS(Feb2026!K3:K100,Feb2026!L3:L100,$A65,Feb2026!M3:M100,$B65)+SUMIFS(Mar2026!K3:K100,Mar2026!L3:L100,$A65,Mar2026!M3:M100,$B65)+SUMIFS(Apr2026!K3:K100,Apr2026!L3:L100,$A65,Apr2026!M3:M100,$B65)+SUMIFS(May2026!K3:K100,May2026!L3:L100,$A65,May2026!M3:M100,$B65)+SUMIFS(Jun2026!K3:K100,Jun2026!L3:L100,$A65,Jun2026!M3:M100,$B65)+SUMIFS(Jul2026!K3:K100,Jul2026!L3:L100,$A65,Jul2026!M3:M100,$B65)+SUMIFS(Aug2026!K3:K100,Aug2026!L3:L100,$A65,Aug2026!M3:M100,$B65)+SUMIFS(Sep2026!K3:K100,Sep2026!L3:L100,$A65,Sep2026!M3:M100,$B65)+SUMIFS(Oct2026!K3:K100,Oct2026!L3:L100,$A65,Oct2026!M3:M100,$B65)+SUMIFS(Nov2026!K3:K100,Nov2026!L3:L100,$A65,Nov2026!M3:M100,$B65)+SUMIFS(Dec2026!K3:K100,Dec2026!L3:L100,$A65,Dec2026!M3:M100,$B65)
A66: Land & Legal | B66: Survey Charges | C66: =SUMIFS(Jan2026!K3:K100,Jan2026!L3:L100,$A66,Jan2026!M3:M100,$B66)+SUMIFS(Feb2026!K3:K100,Feb2026!L3:L100,$A66,Feb2026!M3:M100,$B66)+SUMIFS(Mar2026!K3:K100,Mar2026!L3:L100,$A66,Mar2026!M3:M100,$B66)+SUMIFS(Apr2026!K3:K100,Apr2026!L3:L100,$A66,Apr2026!M3:M100,$B66)+SUMIFS(May2026!K3:K100,May2026!L3:L100,$A66,May2026!M3:M100,$B66)+SUMIFS(Jun2026!K3:K100,Jun2026!L3:L100,$A66,Jun2026!M3:M100,$B66)+SUMIFS(Jul2026!K3:K100,Jul2026!L3:L100,$A66,Jul2026!M3:M100,$B66)+SUMIFS(Aug2026!K3:K100,Aug2026!L3:L100,$A66,Aug2026!M3:M100,$B66)+SUMIFS(Sep2026!K3:K100,Sep2026!L3:L100,$A66,Sep2026!M3:M100,$B66)+SUMIFS(Oct2026!K3:K100,Oct2026!L3:L100,$A66,Oct2026!M3:M100,$B66)+SUMIFS(Nov2026!K3:K100,Nov2026!L3:L100,$A66,Nov2026!M3:M100,$B66)+SUMIFS(Dec2026!K3:K100,Dec2026!L3:L100,$A66,Dec2026!M3:M100,$B66)
A67: Land & Legal | B67: Documentation | C67: =SUMIFS(Jan2026!K3:K100,Jan2026!L3:L100,$A67,Jan2026!M3:M100,$B67)+SUMIFS(Feb2026!K3:K100,Feb2026!L3:L100,$A67,Feb2026!M3:M100,$B67)+SUMIFS(Mar2026!K3:K100,Mar2026!L3:L100,$A67,Mar2026!M3:M100,$B67)+SUMIFS(Apr2026!K3:K100,Apr2026!L3:L100,$A67,Apr2026!M3:M100,$B67)+SUMIFS(May2026!K3:K100,May2026!L3:L100,$A67,May2026!M3:M100,$B67)+SUMIFS(Jun2026!K3:K100,Jun2026!L3:L100,$A67,Jun2026!M3:M100,$B67)+SUMIFS(Jul2026!K3:K100,Jul2026!L3:L100,$A67,Jul2026!M3:M100,$B67)+SUMIFS(Aug2026!K3:K100,Aug2026!L3:L100,$A67,Aug2026!M3:M100,$B67)+SUMIFS(Sep2026!K3:K100,Sep2026!L3:L100,$A67,Sep2026!M3:M100,$B67)+SUMIFS(Oct2026!K3:K100,Oct2026!L3:L100,$A67,Oct2026!M3:M100,$B67)+SUMIFS(Nov2026!K3:K100,Nov2026!L3:L100,$A67,Nov2026!M3:M100,$B67)+SUMIFS(Dec2026!K3:K100,Dec2026!L3:L100,$A67,Dec2026!M3:M100,$B67)
A68: Site Development | B68: Land Clearing | C68: =SUMIFS(Jan2026!K3:K100,Jan2026!L3:L100,$A68,Jan2026!M3:M100,$B68)+SUMIFS(Feb2026!K3:K100,Feb2026!L3:L100,$A68,Feb2026!M3:M100,$B68)+SUMIFS(Mar2026!K3:K100,Mar2026!L3:L100,$A68,Mar2026!M3:M100,$B68)+SUMIFS(Apr2026!K3:K100,Apr2026!L3:L100,$A68,Apr2026!M3:M100,$B68)+SUMIFS(May2026!K3:K100,May2026!L3:L100,$A68,May2026!M3:M100,$B68)+SUMIFS(Jun2026!K3:K100,Jun2026!L3:L100,$A68,Jun2026!M3:M100,$B68)+SUMIFS(Jul2026!K3:K100,Jul2026!L3:L100,$A68,Jul2026!M3:M100,$B68)+SUMIFS(Aug2026!K3:K100,Aug2026!L3:L100,$A68,Aug2026!M3:M100,$B68)+SUMIFS(Sep2026!K3:K100,Sep2026!L3:L100,$A68,Sep2026!M3:M100,$B68)+SUMIFS(Oct2026!K3:K100,Oct2026!L3:L100,$A68,Oct2026!M3:M100,$B68)+SUMIFS(Nov2026!K3:K100,Nov2026!L3:L100,$A68,Nov2026!M3:M100,$B68)+SUMIFS(Dec2026!K3:K100,Dec2026!L3:L100,$A68,Dec2026!M3:M100,$B68)
A69: Site Development | B69: Earthwork & Levelling | C69: =SUMIFS(Jan2026!K3:K100,Jan2026!L3:L100,$A69,Jan2026!M3:M100,$B69)+SUMIFS(Feb2026!K3:K100,Feb2026!L3:L100,$A69,Feb2026!M3:M100,$B69)+SUMIFS(Mar2026!K3:K100,Mar2026!L3:L100,$A69,Mar2026!M3:M100,$B69)+SUMIFS(Apr2026!K3:K100,Apr2026!L3:L100,$A69,Apr2026!M3:M100,$B69)+SUMIFS(May2026!K3:K100,May2026!L3:L100,$A69,May2026!M3:M100,$B69)+SUMIFS(Jun2026!K3:K100,Jun2026!L3:L100,$A69,Jun2026!M3:M100,$B69)+SUMIFS(Jul2026!K3:K100,Jul2026!L3:L100,$A69,Jul2026!M3:M100,$B69)+SUMIFS(Aug2026!K3:K100,Aug2026!L3:L100,$A69,Aug2026!M3:M100,$B69)+SUMIFS(Sep2026!K3:K100,Sep2026!L3:L100,$A69,Sep2026!M3:M100,$B69)+SUMIFS(Oct2026!K3:K100,Oct2026!L3:L100,$A69,Oct2026!M3:M100,$B69)+SUMIFS(Nov2026!K3:K100,Nov2026!L3:L100,$A69,Nov2026!M3:M100,$B69)+SUMIFS(Dec2026!K3:K100,Dec2026!L3:L100,$A69,Dec2026!M3:M100,$B69)
A70: Site Development | B70: Road Formation | C70: =SUMIFS(Jan2026!K3:K100,Jan2026!L3:L100,$A70,Jan2026!M3:M100,$B70)+SUMIFS(Feb2026!K3:K100,Feb2026!L3:L100,$A70,Feb2026!M3:M100,$B70)+SUMIFS(Mar2026!K3:K100,Mar2026!L3:L100,$A70,Mar2026!M3:M100,$B70)+SUMIFS(Apr2026!K3:K100,Apr2026!L3:L100,$A70,Apr2026!M3:M100,$B70)+SUMIFS(May2026!K3:K100,May2026!L3:L100,$A70,May2026!M3:M100,$B70)+SUMIFS(Jun2026!K3:K100,Jun2026!L3:L100,$A70,Jun2026!M3:M100,$B70)+SUMIFS(Jul2026!K3:K100,Jul2026!L3:L100,$A70,Jul2026!M3:M100,$B70)+SUMIFS(Aug2026!K3:K100,Aug2026!L3:L100,$A70,Aug2026!M3:M100,$B70)+SUMIFS(Sep2026!K3:K100,Sep2026!L3:L100,$A70,Sep2026!M3:M100,$B70)+SUMIFS(Oct2026!K3:K100,Oct2026!L3:L100,$A70,Oct2026!M3:M100,$B70)+SUMIFS(Nov2026!K3:K100,Nov2026!L3:L100,$A70,Nov2026!M3:M100,$B70)+SUMIFS(Dec2026!K3:K100,Dec2026!L3:L100,$A70,Dec2026!M3:M100,$B70)
A71: Site Development | B71: Blacktop Roads | C71: =SUMIFS(Jan2026!K3:K100,Jan2026!L3:L100,$A71,Jan2026!M3:M100,$B71)+SUMIFS(Feb2026!K3:K100,Feb2026!L3:L100,$A71,Feb2026!M3:M100,$B71)+SUMIFS(Mar2026!K3:K100,Mar2026!L3:L100,$A71,Mar2026!M3:M100,$B71)+SUMIFS(Apr2026!K3:K100,Apr2026!L3:L100,$A71,Apr2026!M3:M100,$B71)+SUMIFS(May2026!K3:K100,May2026!L3:L100,$A71,May2026!M3:M100,$B71)+SUMIFS(Jun2026!K3:K100,Jun2026!L3:L100,$A71,Jun2026!M3:M100,$B71)+SUMIFS(Jul2026!K3:K100,Jul2026!L3:L100,$A71,Jul2026!M3:M100,$B71)+SUMIFS(Aug2026!K3:K100,Aug2026!L3:L100,$A71,Aug2026!M3:M100,$B71)+SUMIFS(Sep2026!K3:K100,Sep2026!L3:L100,$A71,Sep2026!M3:M100,$B71)+SUMIFS(Oct2026!K3:K100,Oct2026!L3:L100,$A71,Oct2026!M3:M100,$B71)+SUMIFS(Nov2026!K3:K100,Nov2026!L3:L100,$A71,Nov2026!M3:M100,$B71)+SUMIFS(Dec2026!K3:K100,Dec2026!L3:L100,$A71,Dec2026!M3:M100,$B71)
A72: Site Development | B72: Interlocking Pavers | C72: =SUMIFS(Jan2026!K3:K100,Jan2026!L3:L100,$A72,Jan2026!M3:M100,$B72)+SUMIFS(Feb2026!K3:K100,Feb2026!L3:L100,$A72,Feb2026!M3:M100,$B72)+SUMIFS(Mar2026!K3:K100,Mar2026!L3:L100,$A72,Mar2026!M3:M100,$B72)+SUMIFS(Apr2026!K3:K100,Apr2026!L3:L100,$A72,Apr2026!M3:M100,$B72)+SUMIFS(May2026!K3:K100,May2026!L3:L100,$A72,May2026!M3:M100,$B72)+SUMIFS(Jun2026!K3:K100,Jun2026!L3:L100,$A72,Jun2026!M3:M100,$B72)+SUMIFS(Jul2026!K3:K100,Jul2026!L3:L100,$A72,Jul2026!M3:M100,$B72)+SUMIFS(Aug2026!K3:K100,Aug2026!L3:L100,$A72,Aug2026!M3:M100,$B72)+SUMIFS(Sep2026!K3:K100,Sep2026!L3:L100,$A72,Sep2026!M3:M100,$B72)+SUMIFS(Oct2026!K3:K100,Oct2026!L3:L100,$A72,Oct2026!M3:M100,$B72)+SUMIFS(Nov2026!K3:K100,Nov2026!L3:L100,$A72,Nov2026!M3:M100,$B72)+SUMIFS(Dec2026!K3:K100,Dec2026!L3:L100,$A72,Dec2026!M3:M100,$B72)
A73: Site Development | B73: Compound Wall | C73: =SUMIFS(Jan2026!K3:K100,Jan2026!L3:L100,$A73,Jan2026!M3:M100,$B73)+SUMIFS(Feb2026!K3:K100,Feb2026!L3:L100,$A73,Feb2026!M3:M100,$B73)+SUMIFS(Mar2026!K3:K100,Mar2026!L3:L100,$A73,Mar2026!M3:M100,$B73)+SUMIFS(Apr2026!K3:K100,Apr2026!L3:L100,$A73,Apr2026!M3:M100,$B73)+SUMIFS(May2026!K3:K100,May2026!L3:L100,$A73,May2026!M3:M100,$B73)+SUMIFS(Jun2026!K3:K100,Jun2026!L3:L100,$A73,Jun2026!M3:M100,$B73)+SUMIFS(Jul2026!K3:K100,Jul2026!L3:L100,$A73,Jul2026!M3:M100,$B73)+SUMIFS(Aug2026!K3:K100,Aug2026!L3:L100,$A73,Aug2026!M3:M100,$B73)+SUMIFS(Sep2026!K3:K100,Sep2026!L3:L100,$A73,Sep2026!M3:M100,$B73)+SUMIFS(Oct2026!K3:K100,Oct2026!L3:L100,$A73,Oct2026!M3:M100,$B73)+SUMIFS(Nov2026!K3:K100,Nov2026!L3:L100,$A73,Nov2026!M3:M100,$B73)+SUMIFS(Dec2026!K3:K100,Dec2026!L3:L100,$A73,Dec2026!M3:M100,$B73)
A74: Site Development | B74: Entrance Gate | C74: =SUMIFS(Jan2026!K3:K100,Jan2026!L3:L100,$A74,Jan2026!M3:M100,$B74)+SUMIFS(Feb2026!K3:K100,Feb2026!L3:L100,$A74,Feb2026!M3:M100,$B74)+SUMIFS(Mar2026!K3:K100,Mar2026!L3:L100,$A74,Mar2026!M3:M100,$B74)+SUMIFS(Apr2026!K3:K100,Apr2026!L3:L100,$A74,Apr2026!M3:M100,$B74)+SUMIFS(May2026!K3:K100,May2026!L3:L100,$A74,May2026!M3:M100,$B74)+SUMIFS(Jun2026!K3:K100,Jun2026!L3:L100,$A74,Jun2026!M3:M100,$B74)+SUMIFS(Jul2026!K3:K100,Jul2026!L3:L100,$A74,Jul2026!M3:M100,$B74)+SUMIFS(Aug2026!K3:K100,Aug2026!L3:L100,$A74,Aug2026!M3:M100,$B74)+SUMIFS(Sep2026!K3:K100,Sep2026!L3:L100,$A74,Sep2026!M3:M100,$B74)+SUMIFS(Oct2026!K3:K100,Oct2026!L3:L100,$A74,Oct2026!M3:M100,$B74)+SUMIFS(Nov2026!K3:K100,Nov2026!L3:L100,$A74,Nov2026!M3:M100,$B74)+SUMIFS(Dec2026!K3:K100,Dec2026!L3:L100,$A74,Dec2026!M3:M100,$B74)
A75: Site Development | B75: Drainage | C75: =SUMIFS(Jan2026!K3:K100,Jan2026!L3:L100,$A75,Jan2026!M3:M100,$B75)+SUMIFS(Feb2026!K3:K100,Feb2026!L3:L100,$A75,Feb2026!M3:M100,$B75)+SUMIFS(Mar2026!K3:K100,Mar2026!L3:L100,$A75,Mar2026!M3:M100,$B75)+SUMIFS(Apr2026!K3:K100,Apr2026!L3:L100,$A75,Apr2026!M3:M100,$B75)+SUMIFS(May2026!K3:K100,May2026!L3:L100,$A75,May2026!M3:M100,$B75)+SUMIFS(Jun2026!K3:K100,Jun2026!L3:L100,$A75,Jun2026!M3:M100,$B75)+SUMIFS(Jul2026!K3:K100,Jul2026!L3:L100,$A75,Jul2026!M3:M100,$B75)+SUMIFS(Aug2026!K3:K100,Aug2026!L3:L100,$A75,Aug2026!M3:M100,$B75)+SUMIFS(Sep2026!K3:K100,Sep2026!L3:L100,$A75,Sep2026!M3:M100,$B75)+SUMIFS(Oct2026!K3:K100,Oct2026!L3:L100,$A75,Oct2026!M3:M100,$B75)+SUMIFS(Nov2026!K3:K100,Nov2026!L3:L100,$A75,Nov2026!M3:M100,$B75)+SUMIFS(Dec2026!K3:K100,Dec2026!L3:L100,$A75,Dec2026!M3:M100,$B75)
A76: Site Development | B76: Culverts | C76: =SUMIFS(Jan2026!K3:K100,Jan2026!L3:L100,$A76,Jan2026!M3:M100,$B76)+SUMIFS(Feb2026!K3:K100,Feb2026!L3:L100,$A76,Feb2026!M3:M100,$B76)+SUMIFS(Mar2026!K3:K100,Mar2026!L3:L100,$A76,Mar2026!M3:M100,$B76)+SUMIFS(Apr2026!K3:K100,Apr2026!L3:L100,$A76,Apr2026!M3:M100,$B76)+SUMIFS(May2026!K3:K100,May2026!L3:L100,$A76,May2026!M3:M100,$B76)+SUMIFS(Jun2026!K3:K100,Jun2026!L3:L100,$A76,Jun2026!M3:M100,$B76)+SUMIFS(Jul2026!K3:K100,Jul2026!L3:L100,$A76,Jul2026!M3:M100,$B76)+SUMIFS(Aug2026!K3:K100,Aug2026!L3:L100,$A76,Aug2026!M3:M100,$B76)+SUMIFS(Sep2026!K3:K100,Sep2026!L3:L100,$A76,Sep2026!M3:M100,$B76)+SUMIFS(Oct2026!K3:K100,Oct2026!L3:L100,$A76,Oct2026!M3:M100,$B76)+SUMIFS(Nov2026!K3:K100,Nov2026!L3:L100,$A76,Nov2026!M3:M100,$B76)+SUMIFS(Dec2026!K3:K100,Dec2026!L3:L100,$A76,Dec2026!M3:M100,$B76)
A77: Utilities | B77: Borewell | C77: =SUMIFS(Jan2026!K3:K100,Jan2026!L3:L100,$A77,Jan2026!M3:M100,$B77)+SUMIFS(Feb2026!K3:K100,Feb2026!L3:L100,$A77,Feb2026!M3:M100,$B77)+SUMIFS(Mar2026!K3:K100,Mar2026!L3:L100,$A77,Mar2026!M3:M100,$B77)+SUMIFS(Apr2026!K3:K100,Apr2026!L3:L100,$A77,Apr2026!M3:M100,$B77)+SUMIFS(May2026!K3:K100,May2026!L3:L100,$A77,May2026!M3:M100,$B77)+SUMIFS(Jun2026!K3:K100,Jun2026!L3:L100,$A77,Jun2026!M3:M100,$B77)+SUMIFS(Jul2026!K3:K100,Jul2026!L3:L100,$A77,Jul2026!M3:M100,$B77)+SUMIFS(Aug2026!K3:K100,Aug2026!L3:L100,$A77,Aug2026!M3:M100,$B77)+SUMIFS(Sep2026!K3:K100,Sep2026!L3:L100,$A77,Sep2026!M3:M100,$B77)+SUMIFS(Oct2026!K3:K100,Oct2026!L3:L100,$A77,Oct2026!M3:M100,$B77)+SUMIFS(Nov2026!K3:K100,Nov2026!L3:L100,$A77,Nov2026!M3:M100,$B77)+SUMIFS(Dec2026!K3:K100,Dec2026!L3:L100,$A77,Dec2026!M3:M100,$B77)
A78: Utilities | B78: Water Pipelines | C78: =SUMIFS(Jan2026!K3:K100,Jan2026!L3:L100,$A78,Jan2026!M3:M100,$B78)+SUMIFS(Feb2026!K3:K100,Feb2026!L3:L100,$A78,Feb2026!M3:M100,$B78)+SUMIFS(Mar2026!K3:K100,Mar2026!L3:L100,$A78,Mar2026!M3:M100,$B78)+SUMIFS(Apr2026!K3:K100,Apr2026!L3:L100,$A78,Apr2026!M3:M100,$B78)+SUMIFS(May2026!K3:K100,May2026!L3:L100,$A78,May2026!M3:M100,$B78)+SUMIFS(Jun2026!K3:K100,Jun2026!L3:L100,$A78,Jun2026!M3:M100,$B78)+SUMIFS(Jul2026!K3:K100,Jul2026!L3:L100,$A78,Jul2026!M3:M100,$B78)+SUMIFS(Aug2026!K3:K100,Aug2026!L3:L100,$A78,Aug2026!M3:M100,$B78)+SUMIFS(Sep2026!K3:K100,Sep2026!L3:L100,$A78,Sep2026!M3:M100,$B78)+SUMIFS(Oct2026!K3:K100,Oct2026!L3:L100,$A78,Oct2026!M3:M100,$B78)+SUMIFS(Nov2026!K3:K100,Nov2026!L3:L100,$A78,Nov2026!M3:M100,$B78)+SUMIFS(Dec2026!K3:K100,Dec2026!L3:L100,$A78,Dec2026!M3:M100,$B78)
A79: Utilities | B79: Water Tank | C79: =SUMIFS(Jan2026!K3:K100,Jan2026!L3:L100,$A79,Jan2026!M3:M100,$B79)+SUMIFS(Feb2026!K3:K100,Feb2026!L3:L100,$A79,Feb2026!M3:M100,$B79)+SUMIFS(Mar2026!K3:K100,Mar2026!L3:L100,$A79,Mar2026!M3:M100,$B79)+SUMIFS(Apr2026!K3:K100,Apr2026!L3:L100,$A79,Apr2026!M3:M100,$B79)+SUMIFS(May2026!K3:K100,May2026!L3:L100,$A79,May2026!M3:M100,$B79)+SUMIFS(Jun2026!K3:K100,Jun2026!L3:L100,$A79,Jun2026!M3:M100,$B79)+SUMIFS(Jul2026!K3:K100,Jul2026!L3:L100,$A79,Jul2026!M3:M100,$B79)+SUMIFS(Aug2026!K3:K100,Aug2026!L3:L100,$A79,Aug2026!M3:M100,$B79)+SUMIFS(Sep2026!K3:K100,Sep2026!L3:L100,$A79,Sep2026!M3:M100,$B79)+SUMIFS(Oct2026!K3:K100,Oct2026!L3:L100,$A79,Oct2026!M3:M100,$B79)+SUMIFS(Nov2026!K3:K100,Nov2026!L3:L100,$A79,Nov2026!M3:M100,$B79)+SUMIFS(Dec2026!K3:K100,Dec2026!L3:L100,$A79,Dec2026!M3:M100,$B79)
A80: Utilities | B80: Electricity Connection | C80: =SUMIFS(Jan2026!K3:K100,Jan2026!L3:L100,$A80,Jan2026!M3:M100,$B80)+SUMIFS(Feb2026!K3:K100,Feb2026!L3:L100,$A80,Feb2026!M3:M100,$B80)+SUMIFS(Mar2026!K3:K100,Mar2026!L3:L100,$A80,Mar2026!M3:M100,$B80)+SUMIFS(Apr2026!K3:K100,Apr2026!L3:L100,$A80,Apr2026!M3:M100,$B80)+SUMIFS(May2026!K3:K100,May2026!L3:L100,$A80,May2026!M3:M100,$B80)+SUMIFS(Jun2026!K3:K100,Jun2026!L3:L100,$A80,Jun2026!M3:M100,$B80)+SUMIFS(Jul2026!K3:K100,Jul2026!L3:L100,$A80,Jul2026!M3:M100,$B80)+SUMIFS(Aug2026!K3:K100,Aug2026!L3:L100,$A80,Aug2026!M3:M100,$B80)+SUMIFS(Sep2026!K3:K100,Sep2026!L3:L100,$A80,Sep2026!M3:M100,$B80)+SUMIFS(Oct2026!K3:K100,Oct2026!L3:L100,$A80,Oct2026!M3:M100,$B80)+SUMIFS(Nov2026!K3:K100,Nov2026!L3:L100,$A80,Nov2026!M3:M100,$B80)+SUMIFS(Dec2026!K3:K100,Dec2026!L3:L100,$A80,Dec2026!M3:M100,$B80)
A81: Utilities | B81: Transformer | C81: =SUMIFS(Jan2026!K3:K100,Jan2026!L3:L100,$A81,Jan2026!M3:M100,$B81)+SUMIFS(Feb2026!K3:K100,Feb2026!L3:L100,$A81,Feb2026!M3:M100,$B81)+SUMIFS(Mar2026!K3:K100,Mar2026!L3:L100,$A81,Mar2026!M3:M100,$B81)+SUMIFS(Apr2026!K3:K100,Apr2026!L3:L100,$A81,Apr2026!M3:M100,$B81)+SUMIFS(May2026!K3:K100,May2026!L3:L100,$A81,May2026!M3:M100,$B81)+SUMIFS(Jun2026!K3:K100,Jun2026!L3:L100,$A81,Jun2026!M3:M100,$B81)+SUMIFS(Jul2026!K3:K100,Jul2026!L3:L100,$A81,Jul2026!M3:M100,$B81)+SUMIFS(Aug2026!K3:K100,Aug2026!L3:L100,$A81,Aug2026!M3:M100,$B81)+SUMIFS(Sep2026!K3:K100,Sep2026!L3:L100,$A81,Sep2026!M3:M100,$B81)+SUMIFS(Oct2026!K3:K100,Oct2026!L3:L100,$A81,Oct2026!M3:M100,$B81)+SUMIFS(Nov2026!K3:K100,Nov2026!L3:L100,$A81,Nov2026!M3:M100,$B81)+SUMIFS(Dec2026!K3:K100,Dec2026!L3:L100,$A81,Dec2026!M3:M100,$B81)
A82: Utilities | B82: Street Lights | C82: =SUMIFS(Jan2026!K3:K100,Jan2026!L3:L100,$A82,Jan2026!M3:M100,$B82)+SUMIFS(Feb2026!K3:K100,Feb2026!L3:L100,$A82,Feb2026!M3:M100,$B82)+SUMIFS(Mar2026!K3:K100,Mar2026!L3:L100,$A82,Mar2026!M3:M100,$B82)+SUMIFS(Apr2026!K3:K100,Apr2026!L3:L100,$A82,Apr2026!M3:M100,$B82)+SUMIFS(May2026!K3:K100,May2026!L3:L100,$A82,May2026!M3:M100,$B82)+SUMIFS(Jun2026!K3:K100,Jun2026!L3:L100,$A82,Jun2026!M3:M100,$B82)+SUMIFS(Jul2026!K3:K100,Jul2026!L3:L100,$A82,Jul2026!M3:M100,$B82)+SUMIFS(Aug2026!K3:K100,Aug2026!L3:L100,$A82,Aug2026!M3:M100,$B82)+SUMIFS(Sep2026!K3:K100,Sep2026!L3:L100,$A82,Sep2026!M3:M100,$B82)+SUMIFS(Oct2026!K3:K100,Oct2026!L3:L100,$A82,Oct2026!M3:M100,$B82)+SUMIFS(Nov2026!K3:K100,Nov2026!L3:L100,$A82,Nov2026!M3:M100,$B82)+SUMIFS(Dec2026!K3:K100,Dec2026!L3:L100,$A82,Dec2026!M3:M100,$B82)
A83: Utilities | B83: Generator | C83: =SUMIFS(Jan2026!K3:K100,Jan2026!L3:L100,$A83,Jan2026!M3:M100,$B83)+SUMIFS(Feb2026!K3:K100,Feb2026!L3:L100,$A83,Feb2026!M3:M100,$B83)+SUMIFS(Mar2026!K3:K100,Mar2026!L3:L100,$A83,Mar2026!M3:M100,$B83)+SUMIFS(Apr2026!K3:K100,Apr2026!L3:L100,$A83,Apr2026!M3:M100,$B83)+SUMIFS(May2026!K3:K100,May2026!L3:L100,$A83,May2026!M3:M100,$B83)+SUMIFS(Jun2026!K3:K100,Jun2026!L3:L100,$A83,Jun2026!M3:M100,$B83)+SUMIFS(Jul2026!K3:K100,Jul2026!L3:L100,$A83,Jul2026!M3:M100,$B83)+SUMIFS(Aug2026!K3:K100,Aug2026!L3:L100,$A83,Aug2026!M3:M100,$B83)+SUMIFS(Sep2026!K3:K100,Sep2026!L3:L100,$A83,Sep2026!M3:M100,$B83)+SUMIFS(Oct2026!K3:K100,Oct2026!L3:L100,$A83,Oct2026!M3:M100,$B83)+SUMIFS(Nov2026!K3:K100,Nov2026!L3:L100,$A83,Nov2026!M3:M100,$B83)+SUMIFS(Dec2026!K3:K100,Dec2026!L3:L100,$A83,Dec2026!M3:M100,$B83)
...

Sheet Jan2026
A1: Receipts | I1: Payments
A2: SNO | B2: Date | C2: Receipts | D2: Amount | E2: Category | F2: Payment Mode | I2: Date | J2: Payments | K2: Amount | L2: Main Category | M2: Sub-Category | N2: Payment Mode | O2: Comments
A102: Summary
A103: Opening Balance | B103: 0
A104: Total Receipts | B104: =SUM(D3:D100)
A105: Total Payments | B105: =SUM(K3:K100)
A106: Net / Closing Balance | B106: =B103+B104-B105

Sheet Feb2026
A1: Receipts | I1: Payments
A2: SNO | B2: Date | C2: Receipts | D2: Amount | E2: Category | F2: Payment Mode | I2: Date | J2: Payments | K2: Amount | L2: Main Category | M2: Sub-Category | N2: Payment Mode | O2: Comments
A102: Summary
A103: Opening Balance | B103: ='Jan2026'!B106
A104: Total Receipts | B104: =SUM(D3:D100)
A105: Total Payments | B105: =SUM(K3:K100)
A106: Net / Closing Balance | B106: =B103+B104-B105

Sheet Mar2026
A1: Receipts | I1: Payments
A2: SNO | B2: Date | C2: Receipts | D2: Amount | E2: Category | F2: Payment Mode | I2: Date | J2: Payments | K2: Amount | L2: Main Category | M2: Sub-Category | N2: Payment Mode | O2: Comments
A102: Summary
A103: Opening Balance | B103: ='Feb2026'!B106
A104: Total Receipts | B104: =SUM(D3:D100)
A105: Total Payments | B105: =SUM(K3:K100)
A106: Net / Closing Balance | B106: =B103+B104-B105

Sheet Apr2026
A1: Receipts | I1: Payments
A2: SNO | B2: Date | C2: Receipts | D2: Amount | E2: Category | F2: Payment Mode | I2: Date | J2: Payments | K2: Amount | L2: Main Category | M2: Sub-Category | N2: Payment Mode | O2: Comments
A102: Summary
A103: Opening Balance | B103: ='Mar2026'!B106
A104: Total Receipts | B104: =SUM(D3:D100)
A105: Total Payments | B105: =SUM(K3:K100)
A106: Net / Closing Balance | B106: =B103+B104-B105

Sheet May2026
A1: Receipts | I1: Payments
A2: SNO | B2: Date | C2: Receipts | D2: Amount | E2: Category | F2: Payment Mode | I2: Date | J2: Payments | K2: Amount | L2: Main Category | M2: Sub-Category | N2: Payment Mode | O2: Comments
A102: Summary
A103: Opening Balance | B103: ='Apr2026'!B106
A104: Total Receipts | B104: =SUM(D3:D100)
A105: Total Payments | B105: =SUM(K3:K100)
A106: Net / Closing Balance | B106: =B103+B104-B105

Sheet Jun2026
A1: Receipts | I1: Payments
A2: SNO | B2: Date | C2: Receipts | D2: Amount | E2: Category | F2: Payment Mode | I2: Date | J2: Payments | K2: Amount | L2: Main Category | M2: Sub-Category | N2: Payment Mode | O2: Comments
A102: Summary
A103: Opening Balance | B103: ='May2026'!B106
A104: Total Receipts | B104: =SUM(D3:D100)
A105: Total Payments | B105: =SUM(K3:K100)
A106: Net / Closing Balance | B106: =B103+B104-B105

Sheet Jul2026
A1: Receipts | I1: Payments
A2: SNO | B2: Date | C2: Receipts | D2: Amount | E2: Category | F2: Payment Mode | I2: Date | J2: Payments | K2: Amount | L2: Main Category | M2: Sub-Category | N2: Payment Mode | O2: Comments
A102: Summary
A103: Opening Balance | B103: ='Jun2026'!B106
A104: Total Receipts | B104: =SUM(D3:D100)
A105: Total Payments | B105: =SUM(K3:K100)
A106: Net / Closing Balance | B106: =B103+B104-B105

Sheet Aug2026
A1: Receipts | I1: Payments
A2: SNO | B2: Date | C2: Receipts | D2: Amount | E2: Category | F2: Payment Mode | I2: Date | J2: Payments | K2: Amount | L2: Main Category | M2: Sub-Category | N2: Payment Mode | O2: Comments
A102: Summary
A103: Opening Balance | B103: ='Jul2026'!B106
A104: Total Receipts | B104: =SUM(D3:D100)
A105: Total Payments | B105: =SUM(K3:K100)
A106: Net / Closing Balance | B106: =B103+B104-B105

Sheet Sep2026
A1: Receipts | I1: Payments
A2: SNO | B2: Date | C2: Receipts | D2: Amount | E2: Category | F2: Payment Mode | I2: Date | J2: Payments | K2: Amount | L2: Main Category | M2: Sub-Category | N2: Payment Mode | O2: Comments
A102: Summary
A103: Opening Balance | B103: ='Aug2026'!B106
A104: Total Receipts | B104: =SUM(D3:D100)
A105: Total Payments | B105: =SUM(K3:K100)
A106: Net / Closing Balance | B106: =B103+B104-B105

Sheet Oct2026
A1: Receipts | I1: Payments
A2: SNO | B2: Date | C2: Receipts | D2: Amount | E2: Category | F2: Payment Mode | I2: Date | J2: Payments | K2: Amount | L2: Main Category | M2: Sub-Category | N2: Payment Mode | O2: Comments
A102: Summary
A103: Opening Balance | B103: ='Sep2026'!B106
A104: Total Receipts | B104: =SUM(D3:D100)
A105: Total Payments | B105: =SUM(K3:K100)
A106: Net / Closing Balance | B106: =B103+B104-B105

Sheet Nov2026
A1: Receipts | I1: Payments
A2: SNO | B2: Date | C2: Receipts | D2: Amount | E2: Category | F2: Payment Mode | I2: Date | J2: Payments | K2: Amount | L2: Main Category | M2: Sub-Category | N2: Payment Mode | O2: Comments
A102: Summary
A103: Opening Balance | B103: ='Oct2026'!B106
A104: Total Receipts | B104: =SUM(D3:D100)
A105: Total Payments | B105: =SUM(K3:K100)
A106: Net / Closing Balance | B106: =B103+B104-B105

Sheet Dec2026
A1: Receipts | I1: Payments
A2: SNO | B2: Date | C2: Receipts | D2: Amount | E2: Category | F2: Payment Mode | I2: Date | J2: Payments | K2: Amount | L2: Main Category | M2: Sub-Category | N2: Payment Mode | O2: Comments
A102: Summary
A103: Opening Balance | B103: ='Nov2026'!B106
A104: Total Receipts | B104: =SUM(D3:D100)
A105: Total Payments | B105: =SUM(K3:K100)
A106: Net / Closing Balance | B106: =B103+B104-B105

Sheet Categories
A1: Income Categories | C1: Main Category / Sub-category Reference | F1: Unique Main Categories | H1: Sub-categories by Main Category
A2: Income Categories | C2: Main Category | D2: Sub-category | F2: Unique Main Categories | H2: Land & Legal | I2: Site Development | J2: Utilities | K2: Landscaping | L2: Buildings & Amenities | M2: Labour & Contractors | N2: Materials | O2: Operations | P2: Marketing & Sales | Q2: Miscellaneous
A3: Investor Capital | C3: Land & Legal | D3: Land Purchase | F3: Land & Legal | H3: Land Purchase | I3: Land Clearing | J3: Borewell | K3: Plantation | L3: Security Room | M3: Labour Wages | N3: Cement | O3: Security | P3: Advertisement | Q3: Travel Expenses
A4: Partner Contribution | C4: Land & Legal | D4: Advance Payments | F4: Site Development | H4: Advance Payments | I4: Earthwork & Levelling | J4: Water Pipelines | K4: Miyawaki Forest | L4: Site Office | M4: Contractor Payments | N4: Sand | O4: Housekeeping | P4: Flex Boards | Q4: Food & Refreshments
A5: Loan Received | C5: Land & Legal | D5: Registration Charges | F5: Utilities | H5: Registration Charges | I5: Road Formation | J5: Water Tank | K5: Lawn Development | L5: Clubhouse | M5: Machinery Hire | N5: Metal | O5: Fuel & Diesel | P5: Brochures | Q5: Government Fees
A6: Sales | C6: Land & Legal | D6: Stamp Duty | F6: Landscaping | H6: Stamp Duty | I6: Blacktop Roads | J6: Electricity Connection | K6: Irrigation/Drip System | L6: Swimming Pool | M6: Excavator/JCB | N6: Bricks | O6: Vehicle Expenses | P6: Events | Q6: Bank Charges
C7: Land & Legal | D7: Legal Fees | F7: Buildings & Amenities | H7: Legal Fees | I7: Interlocking Pavers | J7: Transformer | K7: Garden Maintenance | L7: Gazebo | M7: Tractor & Transport | N7: Steel | O7: Repairs & Maintenance | P7: Photography & Drone | Q7: Miscellaneous Expenses
C8: Land & Legal | D8: Survey Charges | F8: Labour & Contractors | H8: Survey Charges | I8: Compound Wall | J8: Street Lights | L8: Children's Play Area | N8: Pipes | O8: Office Expenses | P8: Digital Marketing
C9: Land & Legal | D9: Documentation | F9: Materials | H9: Documentation | I9: Entrance Gate | J9: Generator | L9: Sports Courts | N9: Electrical Materials | O9: Internet & Phone
C10: Site Development | D10: Land Clearing | F10: Operations | I10: Drainage | L10: Toilets | N10: Paint
C11: Site Development | D11: Earthwork & Levelling | F11: Marketing & Sales | I11: Culverts | N11: Tiles
C12: Site Development | D12: Road Formation | F12: Miscellaneous
C13: Site Development | D13: Blacktop Roads
C14: Site Development | D14: Interlocking Pavers
C15: Site Development | D15: Compound Wall
C16: Site Development | D16: Entrance Gate
C17: Site Development | D17: Drainage
C18: Site Development | D18: Culverts
C19: Utilities | D19: Borewell
C20: Utilities | D20: Water Pipelines
C21: Utilities | D21: Water Tank
C22: Utilities | D22: Electricity Connection
C23: Utilities | D23: Transformer
C24: Utilities | D24: Street Lights
... C70: Miscellaneous | D70: Miscellaneous Expenses
